__main__ - ERROR - 2023-10-26 09:59:59,571 - Failed to run workflow due to error:
[Errno 2] No such file or directory: 'pyenv'
__main__ - ERROR - 2023-10-26 09:59:59,572 - Traceback (most recent call last):
  File "/home/arthur/Documents/ifc/tc/code/sipd-mlops/cmd/main.py", line 49, in <module>
    workflow()
  File "/home/arthur/Documents/ifc/tc/code/sipd-mlops/mlops/lib/python3.10/site-packages/click/core.py", line 1157, in __call__
    return self.main(*args, **kwargs)
  File "/home/arthur/Documents/ifc/tc/code/sipd-mlops/mlops/lib/python3.10/site-packages/click/core.py", line 1078, in main
    rv = self.invoke(ctx)
  File "/home/arthur/Documents/ifc/tc/code/sipd-mlops/mlops/lib/python3.10/site-packages/click/core.py", line 1434, in invoke
    return ctx.invoke(self.callback, **ctx.params)
  File "/home/arthur/Documents/ifc/tc/code/sipd-mlops/mlops/lib/python3.10/site-packages/click/core.py", line 783, in invoke
    return __callback(*args, **kwargs)
  File "/home/arthur/Documents/ifc/tc/code/sipd-mlops/cmd/main.py", line 28, in workflow
    _run("prepare_train_and_test_dataset")
  File "/home/arthur/Documents/ifc/tc/code/sipd-mlops/cmd/main.py", line 16, in _run
    submitted_run = mlflow.run(".", entrypoint)
  File "/home/arthur/Documents/ifc/tc/code/sipd-mlops/mlops/lib/python3.10/site-packages/mlflow/projects/__init__.py", line 337, in run
    submitted_run_obj = _run(
  File "/home/arthur/Documents/ifc/tc/code/sipd-mlops/mlops/lib/python3.10/site-packages/mlflow/projects/__init__.py", line 106, in _run
    submitted_run = backend.run(
  File "/home/arthur/Documents/ifc/tc/code/sipd-mlops/mlops/lib/python3.10/site-packages/mlflow/projects/backend/local.py", line 160, in run
    python_bin_path = _install_python(python_env.python, pyenv_root=pyenv_root)
  File "/home/arthur/Documents/ifc/tc/code/sipd-mlops/mlops/lib/python3.10/site-packages/mlflow/utils/virtualenv.py", line 125, in _install_python
    else _find_latest_installable_python_version(version)
  File "/home/arthur/Documents/ifc/tc/code/sipd-mlops/mlops/lib/python3.10/site-packages/mlflow/utils/virtualenv.py", line 101, in _find_latest_installable_python_version
    lines = _exec_cmd(
  File "/home/arthur/Documents/ifc/tc/code/sipd-mlops/mlops/lib/python3.10/site-packages/mlflow/utils/process.py", line 95, in _exec_cmd
    process = subprocess.Popen(
  File "/usr/lib/python3.10/subprocess.py", line 971, in __init__
    self._execute_child(args, executable, preexec_fn, close_fds,
  File "/usr/lib/python3.10/subprocess.py", line 1863, in _execute_child
    raise child_exception_type(errno_num, err_msg, err_filename)
FileNotFoundError: [Errno 2] No such file or directory: 'pyenv'

__main__ - ERROR - 2023-10-26 10:11:25,844 - Failed to run workflow due to error:
[Errno 2] No such file or directory: 'pyenv'
__main__ - ERROR - 2023-10-26 10:11:25,845 - Traceback (most recent call last):
  File "/home/arthur/Documents/ifc/tc/code/sipd-mlops/cmd/main.py", line 49, in <module>
    workflow()
  File "/home/arthur/Documents/ifc/tc/code/sipd-mlops/mlops/lib/python3.10/site-packages/click/core.py", line 1157, in __call__
    return self.main(*args, **kwargs)
  File "/home/arthur/Documents/ifc/tc/code/sipd-mlops/mlops/lib/python3.10/site-packages/click/core.py", line 1078, in main
    rv = self.invoke(ctx)
  File "/home/arthur/Documents/ifc/tc/code/sipd-mlops/mlops/lib/python3.10/site-packages/click/core.py", line 1434, in invoke
    return ctx.invoke(self.callback, **ctx.params)
  File "/home/arthur/Documents/ifc/tc/code/sipd-mlops/mlops/lib/python3.10/site-packages/click/core.py", line 783, in invoke
    return __callback(*args, **kwargs)
  File "/home/arthur/Documents/ifc/tc/code/sipd-mlops/cmd/main.py", line 28, in workflow
    _run("prepare_train_and_test_dataset")
  File "/home/arthur/Documents/ifc/tc/code/sipd-mlops/cmd/main.py", line 16, in _run
    submitted_run = mlflow.run(".", entrypoint)
  File "/home/arthur/Documents/ifc/tc/code/sipd-mlops/mlops/lib/python3.10/site-packages/mlflow/projects/__init__.py", line 337, in run
    submitted_run_obj = _run(
  File "/home/arthur/Documents/ifc/tc/code/sipd-mlops/mlops/lib/python3.10/site-packages/mlflow/projects/__init__.py", line 106, in _run
    submitted_run = backend.run(
  File "/home/arthur/Documents/ifc/tc/code/sipd-mlops/mlops/lib/python3.10/site-packages/mlflow/projects/backend/local.py", line 160, in run
    python_bin_path = _install_python(python_env.python, pyenv_root=pyenv_root)
  File "/home/arthur/Documents/ifc/tc/code/sipd-mlops/mlops/lib/python3.10/site-packages/mlflow/utils/virtualenv.py", line 125, in _install_python
    else _find_latest_installable_python_version(version)
  File "/home/arthur/Documents/ifc/tc/code/sipd-mlops/mlops/lib/python3.10/site-packages/mlflow/utils/virtualenv.py", line 101, in _find_latest_installable_python_version
    lines = _exec_cmd(
  File "/home/arthur/Documents/ifc/tc/code/sipd-mlops/mlops/lib/python3.10/site-packages/mlflow/utils/process.py", line 95, in _exec_cmd
    process = subprocess.Popen(
  File "/usr/lib/python3.10/subprocess.py", line 971, in __init__
    self._execute_child(args, executable, preexec_fn, close_fds,
  File "/usr/lib/python3.10/subprocess.py", line 1863, in _execute_child
    raise child_exception_type(errno_num, err_msg, err_filename)
FileNotFoundError: [Errno 2] No such file or directory: 'pyenv'

__main__ - ERROR - 2023-10-26 10:12:17,971 - Failed to run workflow due to error:
Run (ID '03af0e7496294800a683949572d378bb') failed
__main__ - ERROR - 2023-10-26 10:12:17,974 - Traceback (most recent call last):
  File "/home/arthur/Documents/ifc/tc/code/sipd-mlops/cmd/main.py", line 49, in <module>
    workflow()
  File "/home/arthur/Documents/ifc/tc/code/sipd-mlops/mlops/lib/python3.10/site-packages/click/core.py", line 1157, in __call__
    return self.main(*args, **kwargs)
  File "/home/arthur/Documents/ifc/tc/code/sipd-mlops/mlops/lib/python3.10/site-packages/click/core.py", line 1078, in main
    rv = self.invoke(ctx)
  File "/home/arthur/Documents/ifc/tc/code/sipd-mlops/mlops/lib/python3.10/site-packages/click/core.py", line 1434, in invoke
    return ctx.invoke(self.callback, **ctx.params)
  File "/home/arthur/Documents/ifc/tc/code/sipd-mlops/mlops/lib/python3.10/site-packages/click/core.py", line 783, in invoke
    return __callback(*args, **kwargs)
  File "/home/arthur/Documents/ifc/tc/code/sipd-mlops/cmd/main.py", line 28, in workflow
    _run("prepare_train_and_test_dataset")
  File "/home/arthur/Documents/ifc/tc/code/sipd-mlops/cmd/main.py", line 16, in _run
    submitted_run = mlflow.run(".", entrypoint)
  File "/home/arthur/Documents/ifc/tc/code/sipd-mlops/mlops/lib/python3.10/site-packages/mlflow/projects/__init__.py", line 354, in run
    _wait_for(submitted_run_obj)
  File "/home/arthur/Documents/ifc/tc/code/sipd-mlops/mlops/lib/python3.10/site-packages/mlflow/projects/__init__.py", line 371, in _wait_for
    raise ExecutionException(f"Run (ID '{run_id}') failed")
mlflow.exceptions.ExecutionException: Run (ID '03af0e7496294800a683949572d378bb') failed

__main__ - ERROR - 2023-10-26 10:17:28,507 - Failed to run workflow due to error:
Run (ID '4edfb91e346c42c6b6ec6c5e449533ae') failed
__main__ - ERROR - 2023-10-26 10:17:28,508 - Traceback (most recent call last):
  File "/home/arthur/Documents/ifc/tc/code/sipd-mlops/cmd/main.py", line 49, in <module>
    workflow()
  File "/home/arthur/.mlflow/envs/mlflow-ee2151125638920885a7c5b8ea4d8ebbb2e906cb/lib/python3.10/site-packages/click/core.py", line 1157, in __call__
    return self.main(*args, **kwargs)
  File "/home/arthur/.mlflow/envs/mlflow-ee2151125638920885a7c5b8ea4d8ebbb2e906cb/lib/python3.10/site-packages/click/core.py", line 1078, in main
    rv = self.invoke(ctx)
  File "/home/arthur/.mlflow/envs/mlflow-ee2151125638920885a7c5b8ea4d8ebbb2e906cb/lib/python3.10/site-packages/click/core.py", line 1434, in invoke
    return ctx.invoke(self.callback, **ctx.params)
  File "/home/arthur/.mlflow/envs/mlflow-ee2151125638920885a7c5b8ea4d8ebbb2e906cb/lib/python3.10/site-packages/click/core.py", line 783, in invoke
    return __callback(*args, **kwargs)
  File "/home/arthur/Documents/ifc/tc/code/sipd-mlops/cmd/main.py", line 33, in workflow
    _run("test_model")
  File "/home/arthur/Documents/ifc/tc/code/sipd-mlops/cmd/main.py", line 16, in _run
    submitted_run = mlflow.run(".", entrypoint)
  File "/home/arthur/.mlflow/envs/mlflow-ee2151125638920885a7c5b8ea4d8ebbb2e906cb/lib/python3.10/site-packages/mlflow/projects/__init__.py", line 354, in run
    _wait_for(submitted_run_obj)
  File "/home/arthur/.mlflow/envs/mlflow-ee2151125638920885a7c5b8ea4d8ebbb2e906cb/lib/python3.10/site-packages/mlflow/projects/__init__.py", line 371, in _wait_for
    raise ExecutionException(f"Run (ID '{run_id}') failed")
mlflow.exceptions.ExecutionException: Run (ID '4edfb91e346c42c6b6ec6c5e449533ae') failed

__main__ - ERROR - 2023-10-26 10:20:03,119 - Failed to run workflow due to error:
Run (ID 'b5c44aae91614061971084b1dcca8a7d') failed
__main__ - ERROR - 2023-10-26 10:20:03,122 - Traceback (most recent call last):
  File "/home/arthur/Documents/ifc/tc/code/sipd-mlops/cmd/main.py", line 49, in <module>
    workflow()
  File "/home/arthur/.mlflow/envs/mlflow-ee2151125638920885a7c5b8ea4d8ebbb2e906cb/lib/python3.10/site-packages/click/core.py", line 1157, in __call__
    return self.main(*args, **kwargs)
  File "/home/arthur/.mlflow/envs/mlflow-ee2151125638920885a7c5b8ea4d8ebbb2e906cb/lib/python3.10/site-packages/click/core.py", line 1078, in main
    rv = self.invoke(ctx)
  File "/home/arthur/.mlflow/envs/mlflow-ee2151125638920885a7c5b8ea4d8ebbb2e906cb/lib/python3.10/site-packages/click/core.py", line 1434, in invoke
    return ctx.invoke(self.callback, **ctx.params)
  File "/home/arthur/.mlflow/envs/mlflow-ee2151125638920885a7c5b8ea4d8ebbb2e906cb/lib/python3.10/site-packages/click/core.py", line 783, in invoke
    return __callback(*args, **kwargs)
  File "/home/arthur/Documents/ifc/tc/code/sipd-mlops/cmd/main.py", line 33, in workflow
    _run("test_model")
  File "/home/arthur/Documents/ifc/tc/code/sipd-mlops/cmd/main.py", line 16, in _run
    submitted_run = mlflow.run(".", entrypoint)
  File "/home/arthur/.mlflow/envs/mlflow-ee2151125638920885a7c5b8ea4d8ebbb2e906cb/lib/python3.10/site-packages/mlflow/projects/__init__.py", line 354, in run
    _wait_for(submitted_run_obj)
  File "/home/arthur/.mlflow/envs/mlflow-ee2151125638920885a7c5b8ea4d8ebbb2e906cb/lib/python3.10/site-packages/mlflow/projects/__init__.py", line 371, in _wait_for
    raise ExecutionException(f"Run (ID '{run_id}') failed")
mlflow.exceptions.ExecutionException: Run (ID 'b5c44aae91614061971084b1dcca8a7d') failed

__main__ - ERROR - 2023-10-26 10:22:29,441 - Failed to run workflow due to error:
Run (ID 'b7f534bac0a84af1ad0a067f577024ee') failed
__main__ - ERROR - 2023-10-26 10:22:29,443 - Traceback (most recent call last):
  File "/home/arthur/Documents/ifc/tc/code/sipd-mlops/cmd/main.py", line 49, in <module>
    workflow()
  File "/home/arthur/.mlflow/envs/mlflow-ee2151125638920885a7c5b8ea4d8ebbb2e906cb/lib/python3.10/site-packages/click/core.py", line 1157, in __call__
    return self.main(*args, **kwargs)
  File "/home/arthur/.mlflow/envs/mlflow-ee2151125638920885a7c5b8ea4d8ebbb2e906cb/lib/python3.10/site-packages/click/core.py", line 1078, in main
    rv = self.invoke(ctx)
  File "/home/arthur/.mlflow/envs/mlflow-ee2151125638920885a7c5b8ea4d8ebbb2e906cb/lib/python3.10/site-packages/click/core.py", line 1434, in invoke
    return ctx.invoke(self.callback, **ctx.params)
  File "/home/arthur/.mlflow/envs/mlflow-ee2151125638920885a7c5b8ea4d8ebbb2e906cb/lib/python3.10/site-packages/click/core.py", line 783, in invoke
    return __callback(*args, **kwargs)
  File "/home/arthur/Documents/ifc/tc/code/sipd-mlops/cmd/main.py", line 33, in workflow
    _run("test_model")
  File "/home/arthur/Documents/ifc/tc/code/sipd-mlops/cmd/main.py", line 16, in _run
    submitted_run = mlflow.run(".", entrypoint)
  File "/home/arthur/.mlflow/envs/mlflow-ee2151125638920885a7c5b8ea4d8ebbb2e906cb/lib/python3.10/site-packages/mlflow/projects/__init__.py", line 354, in run
    _wait_for(submitted_run_obj)
  File "/home/arthur/.mlflow/envs/mlflow-ee2151125638920885a7c5b8ea4d8ebbb2e906cb/lib/python3.10/site-packages/mlflow/projects/__init__.py", line 371, in _wait_for
    raise ExecutionException(f"Run (ID '{run_id}') failed")
mlflow.exceptions.ExecutionException: Run (ID 'b7f534bac0a84af1ad0a067f577024ee') failed

__main__ - ERROR - 2023-10-26 10:25:46,012 - Failed to run workflow due to error:
Run (ID '0299b08712b64216944fc67178984b62') failed
__main__ - ERROR - 2023-10-26 10:25:46,013 - Traceback (most recent call last):
  File "/home/arthur/Documents/ifc/tc/code/sipd-mlops/cmd/main.py", line 49, in <module>
    workflow()
  File "/home/arthur/.mlflow/envs/mlflow-ee2151125638920885a7c5b8ea4d8ebbb2e906cb/lib/python3.10/site-packages/click/core.py", line 1157, in __call__
    return self.main(*args, **kwargs)
  File "/home/arthur/.mlflow/envs/mlflow-ee2151125638920885a7c5b8ea4d8ebbb2e906cb/lib/python3.10/site-packages/click/core.py", line 1078, in main
    rv = self.invoke(ctx)
  File "/home/arthur/.mlflow/envs/mlflow-ee2151125638920885a7c5b8ea4d8ebbb2e906cb/lib/python3.10/site-packages/click/core.py", line 1434, in invoke
    return ctx.invoke(self.callback, **ctx.params)
  File "/home/arthur/.mlflow/envs/mlflow-ee2151125638920885a7c5b8ea4d8ebbb2e906cb/lib/python3.10/site-packages/click/core.py", line 783, in invoke
    return __callback(*args, **kwargs)
  File "/home/arthur/Documents/ifc/tc/code/sipd-mlops/cmd/main.py", line 33, in workflow
    _run("test_model")
  File "/home/arthur/Documents/ifc/tc/code/sipd-mlops/cmd/main.py", line 16, in _run
    submitted_run = mlflow.run(".", entrypoint)
  File "/home/arthur/.mlflow/envs/mlflow-ee2151125638920885a7c5b8ea4d8ebbb2e906cb/lib/python3.10/site-packages/mlflow/projects/__init__.py", line 354, in run
    _wait_for(submitted_run_obj)
  File "/home/arthur/.mlflow/envs/mlflow-ee2151125638920885a7c5b8ea4d8ebbb2e906cb/lib/python3.10/site-packages/mlflow/projects/__init__.py", line 371, in _wait_for
    raise ExecutionException(f"Run (ID '{run_id}') failed")
mlflow.exceptions.ExecutionException: Run (ID '0299b08712b64216944fc67178984b62') failed

__main__ - ERROR - 2023-10-27 00:40:22,243 - Failed to run workflow due to error:
Run (ID '13bd76d0b1dc47ecac9c43ba78a6c1d0') failed
__main__ - ERROR - 2023-10-27 00:40:22,246 - Traceback (most recent call last):
  File "/home/arthur/Documents/ifc/tc/code/sipd-mlops/cmd/main.py", line 49, in <module>
    workflow()
  File "/home/arthur/.mlflow/envs/mlflow-ee2151125638920885a7c5b8ea4d8ebbb2e906cb/lib/python3.10/site-packages/click/core.py", line 1157, in __call__
    return self.main(*args, **kwargs)
  File "/home/arthur/.mlflow/envs/mlflow-ee2151125638920885a7c5b8ea4d8ebbb2e906cb/lib/python3.10/site-packages/click/core.py", line 1078, in main
    rv = self.invoke(ctx)
  File "/home/arthur/.mlflow/envs/mlflow-ee2151125638920885a7c5b8ea4d8ebbb2e906cb/lib/python3.10/site-packages/click/core.py", line 1434, in invoke
    return ctx.invoke(self.callback, **ctx.params)
  File "/home/arthur/.mlflow/envs/mlflow-ee2151125638920885a7c5b8ea4d8ebbb2e906cb/lib/python3.10/site-packages/click/core.py", line 783, in invoke
    return __callback(*args, **kwargs)
  File "/home/arthur/Documents/ifc/tc/code/sipd-mlops/cmd/main.py", line 33, in workflow
    _run("test_model")
  File "/home/arthur/Documents/ifc/tc/code/sipd-mlops/cmd/main.py", line 16, in _run
    submitted_run = mlflow.run(".", entrypoint)
  File "/home/arthur/.mlflow/envs/mlflow-ee2151125638920885a7c5b8ea4d8ebbb2e906cb/lib/python3.10/site-packages/mlflow/projects/__init__.py", line 354, in run
    _wait_for(submitted_run_obj)
  File "/home/arthur/.mlflow/envs/mlflow-ee2151125638920885a7c5b8ea4d8ebbb2e906cb/lib/python3.10/site-packages/mlflow/projects/__init__.py", line 371, in _wait_for
    raise ExecutionException(f"Run (ID '{run_id}') failed")
mlflow.exceptions.ExecutionException: Run (ID '13bd76d0b1dc47ecac9c43ba78a6c1d0') failed

