__main__ - ERROR - 2023-10-14 15:09:36,857 - Failed to run workflow due to error:
No value given for missing parameters: 'files_path'
__main__ - ERROR - 2023-10-14 15:09:36,858 - Traceback (most recent call last):
  File "/home/arthur/Documents/ifc/tc/code/sipd-mlops/cmd/main.py", line 48, in <module>
    workflow()
  File "/home/arthur/.mlflow/envs/mlflow-ee2151125638920885a7c5b8ea4d8ebbb2e906cb/lib/python3.10/site-packages/click/core.py", line 1157, in __call__
    return self.main(*args, **kwargs)
  File "/home/arthur/.mlflow/envs/mlflow-ee2151125638920885a7c5b8ea4d8ebbb2e906cb/lib/python3.10/site-packages/click/core.py", line 1078, in main
    rv = self.invoke(ctx)
  File "/home/arthur/.mlflow/envs/mlflow-ee2151125638920885a7c5b8ea4d8ebbb2e906cb/lib/python3.10/site-packages/click/core.py", line 1434, in invoke
    return ctx.invoke(self.callback, **ctx.params)
  File "/home/arthur/.mlflow/envs/mlflow-ee2151125638920885a7c5b8ea4d8ebbb2e906cb/lib/python3.10/site-packages/click/core.py", line 783, in invoke
    return __callback(*args, **kwargs)
  File "/home/arthur/Documents/ifc/tc/code/sipd-mlops/cmd/main.py", line 28, in workflow
    _run("prepare_train_dataset")
  File "/home/arthur/Documents/ifc/tc/code/sipd-mlops/cmd/main.py", line 16, in _run
    submitted_run = mlflow.run(".", entrypoint, parameters = parameters)
  File "/home/arthur/.mlflow/envs/mlflow-ee2151125638920885a7c5b8ea4d8ebbb2e906cb/lib/python3.10/site-packages/mlflow/projects/__init__.py", line 337, in run
    submitted_run_obj = _run(
  File "/home/arthur/.mlflow/envs/mlflow-ee2151125638920885a7c5b8ea4d8ebbb2e906cb/lib/python3.10/site-packages/mlflow/projects/__init__.py", line 106, in _run
    submitted_run = backend.run(
  File "/home/arthur/.mlflow/envs/mlflow-ee2151125638920885a7c5b8ea4d8ebbb2e906cb/lib/python3.10/site-packages/mlflow/projects/backend/local.py", line 80, in run
    work_dir = fetch_and_validate_project(project_uri, version, entry_point, params)
  File "/home/arthur/.mlflow/envs/mlflow-ee2151125638920885a7c5b8ea4d8ebbb2e906cb/lib/python3.10/site-packages/mlflow/projects/utils.py", line 140, in fetch_and_validate_project
    project.get_entry_point(entry_point)._validate_parameters(parameters)
  File "/home/arthur/.mlflow/envs/mlflow-ee2151125638920885a7c5b8ea4d8ebbb2e906cb/lib/python3.10/site-packages/mlflow/projects/_project_spec.py", line 195, in _validate_parameters
    raise ExecutionException(
mlflow.exceptions.ExecutionException: No value given for missing parameters: 'files_path'

__main__ - ERROR - 2023-10-14 15:39:28,372 - Failed to run workflow due to error:
not enough arguments for format string
__main__ - ERROR - 2023-10-14 15:39:28,373 - Traceback (most recent call last):
  File "/home/arthur/Documents/ifc/tc/code/sipd-mlops/cmd/main.py", line 48, in <module>
    workflow()
  File "/home/arthur/.mlflow/envs/mlflow-ee2151125638920885a7c5b8ea4d8ebbb2e906cb/lib/python3.10/site-packages/click/core.py", line 1157, in __call__
    return self.main(*args, **kwargs)
  File "/home/arthur/.mlflow/envs/mlflow-ee2151125638920885a7c5b8ea4d8ebbb2e906cb/lib/python3.10/site-packages/click/core.py", line 1078, in main
    rv = self.invoke(ctx)
  File "/home/arthur/.mlflow/envs/mlflow-ee2151125638920885a7c5b8ea4d8ebbb2e906cb/lib/python3.10/site-packages/click/core.py", line 1434, in invoke
    return ctx.invoke(self.callback, **ctx.params)
  File "/home/arthur/.mlflow/envs/mlflow-ee2151125638920885a7c5b8ea4d8ebbb2e906cb/lib/python3.10/site-packages/click/core.py", line 783, in invoke
    return __callback(*args, **kwargs)
  File "/home/arthur/Documents/ifc/tc/code/sipd-mlops/cmd/main.py", line 28, in workflow
    _run("prepare_train_dataset")
  File "/home/arthur/Documents/ifc/tc/code/sipd-mlops/cmd/main.py", line 13, in _run
    "Launching new run for entrypoint=%s and parameters=%s"
TypeError: not enough arguments for format string

__main__ - ERROR - 2023-10-14 15:53:13,321 - Failed to run workflow due to error:
Could not find train among entry points ['prepare_train_dataset', 'prepare_test_dataset', 'prepare_experiments_dataset', 'main', 'validate'] or interpret train as a runnable script. Supported script file extensions: ['.py', '.sh']
__main__ - ERROR - 2023-10-14 15:53:13,322 - Traceback (most recent call last):
  File "/home/arthur/Documents/ifc/tc/code/sipd-mlops/cmd/main.py", line 48, in <module>
    workflow()
  File "/home/arthur/.mlflow/envs/mlflow-ee2151125638920885a7c5b8ea4d8ebbb2e906cb/lib/python3.10/site-packages/click/core.py", line 1157, in __call__
    return self.main(*args, **kwargs)
  File "/home/arthur/.mlflow/envs/mlflow-ee2151125638920885a7c5b8ea4d8ebbb2e906cb/lib/python3.10/site-packages/click/core.py", line 1078, in main
    rv = self.invoke(ctx)
  File "/home/arthur/.mlflow/envs/mlflow-ee2151125638920885a7c5b8ea4d8ebbb2e906cb/lib/python3.10/site-packages/click/core.py", line 1434, in invoke
    return ctx.invoke(self.callback, **ctx.params)
  File "/home/arthur/.mlflow/envs/mlflow-ee2151125638920885a7c5b8ea4d8ebbb2e906cb/lib/python3.10/site-packages/click/core.py", line 783, in invoke
    return __callback(*args, **kwargs)
  File "/home/arthur/Documents/ifc/tc/code/sipd-mlops/cmd/main.py", line 33, in workflow
    _run("train")
  File "/home/arthur/Documents/ifc/tc/code/sipd-mlops/cmd/main.py", line 16, in _run
    submitted_run = mlflow.run(".", entrypoint)
  File "/home/arthur/.mlflow/envs/mlflow-ee2151125638920885a7c5b8ea4d8ebbb2e906cb/lib/python3.10/site-packages/mlflow/projects/__init__.py", line 337, in run
    submitted_run_obj = _run(
  File "/home/arthur/.mlflow/envs/mlflow-ee2151125638920885a7c5b8ea4d8ebbb2e906cb/lib/python3.10/site-packages/mlflow/projects/__init__.py", line 106, in _run
    submitted_run = backend.run(
  File "/home/arthur/.mlflow/envs/mlflow-ee2151125638920885a7c5b8ea4d8ebbb2e906cb/lib/python3.10/site-packages/mlflow/projects/backend/local.py", line 80, in run
    work_dir = fetch_and_validate_project(project_uri, version, entry_point, params)
  File "/home/arthur/.mlflow/envs/mlflow-ee2151125638920885a7c5b8ea4d8ebbb2e906cb/lib/python3.10/site-packages/mlflow/projects/utils.py", line 140, in fetch_and_validate_project
    project.get_entry_point(entry_point)._validate_parameters(parameters)
  File "/home/arthur/.mlflow/envs/mlflow-ee2151125638920885a7c5b8ea4d8ebbb2e906cb/lib/python3.10/site-packages/mlflow/projects/_project_spec.py", line 174, in get_entry_point
    raise ExecutionException(
mlflow.exceptions.ExecutionException: Could not find train among entry points ['prepare_train_dataset', 'prepare_test_dataset', 'prepare_experiments_dataset', 'main', 'validate'] or interpret train as a runnable script. Supported script file extensions: ['.py', '.sh']

__main__ - ERROR - 2023-10-14 15:56:26,654 - Failed to run workflow due to error:
Could not find train among entry points ['prepare_train_dataset', 'prepare_test_dataset', 'prepare_experiments_dataset', 'main', 'validate'] or interpret train as a runnable script. Supported script file extensions: ['.py', '.sh']
__main__ - ERROR - 2023-10-14 15:56:26,654 - Traceback (most recent call last):
  File "/home/arthur/Documents/ifc/tc/code/sipd-mlops/cmd/main.py", line 48, in <module>
    workflow()
  File "/home/arthur/.mlflow/envs/mlflow-ee2151125638920885a7c5b8ea4d8ebbb2e906cb/lib/python3.10/site-packages/click/core.py", line 1157, in __call__
    return self.main(*args, **kwargs)
  File "/home/arthur/.mlflow/envs/mlflow-ee2151125638920885a7c5b8ea4d8ebbb2e906cb/lib/python3.10/site-packages/click/core.py", line 1078, in main
    rv = self.invoke(ctx)
  File "/home/arthur/.mlflow/envs/mlflow-ee2151125638920885a7c5b8ea4d8ebbb2e906cb/lib/python3.10/site-packages/click/core.py", line 1434, in invoke
    return ctx.invoke(self.callback, **ctx.params)
  File "/home/arthur/.mlflow/envs/mlflow-ee2151125638920885a7c5b8ea4d8ebbb2e906cb/lib/python3.10/site-packages/click/core.py", line 783, in invoke
    return __callback(*args, **kwargs)
  File "/home/arthur/Documents/ifc/tc/code/sipd-mlops/cmd/main.py", line 33, in workflow
    _run("train")
  File "/home/arthur/Documents/ifc/tc/code/sipd-mlops/cmd/main.py", line 16, in _run
    submitted_run = mlflow.run(".", entrypoint)
  File "/home/arthur/.mlflow/envs/mlflow-ee2151125638920885a7c5b8ea4d8ebbb2e906cb/lib/python3.10/site-packages/mlflow/projects/__init__.py", line 337, in run
    submitted_run_obj = _run(
  File "/home/arthur/.mlflow/envs/mlflow-ee2151125638920885a7c5b8ea4d8ebbb2e906cb/lib/python3.10/site-packages/mlflow/projects/__init__.py", line 106, in _run
    submitted_run = backend.run(
  File "/home/arthur/.mlflow/envs/mlflow-ee2151125638920885a7c5b8ea4d8ebbb2e906cb/lib/python3.10/site-packages/mlflow/projects/backend/local.py", line 80, in run
    work_dir = fetch_and_validate_project(project_uri, version, entry_point, params)
  File "/home/arthur/.mlflow/envs/mlflow-ee2151125638920885a7c5b8ea4d8ebbb2e906cb/lib/python3.10/site-packages/mlflow/projects/utils.py", line 140, in fetch_and_validate_project
    project.get_entry_point(entry_point)._validate_parameters(parameters)
  File "/home/arthur/.mlflow/envs/mlflow-ee2151125638920885a7c5b8ea4d8ebbb2e906cb/lib/python3.10/site-packages/mlflow/projects/_project_spec.py", line 174, in get_entry_point
    raise ExecutionException(
mlflow.exceptions.ExecutionException: Could not find train among entry points ['prepare_train_dataset', 'prepare_test_dataset', 'prepare_experiments_dataset', 'main', 'validate'] or interpret train as a runnable script. Supported script file extensions: ['.py', '.sh']

__main__ - ERROR - 2023-10-14 15:56:44,245 - Failed to run workflow due to error:
Could not find train among entry points ['prepare_train_dataset', 'prepare_test_dataset', 'prepare_experiments_dataset', 'main', 'validate'] or interpret train as a runnable script. Supported script file extensions: ['.py', '.sh']
__main__ - ERROR - 2023-10-14 15:56:44,246 - Traceback (most recent call last):
  File "/home/arthur/Documents/ifc/tc/code/sipd-mlops/cmd/main.py", line 48, in <module>
    workflow()
  File "/home/arthur/.mlflow/envs/mlflow-ee2151125638920885a7c5b8ea4d8ebbb2e906cb/lib/python3.10/site-packages/click/core.py", line 1157, in __call__
    return self.main(*args, **kwargs)
  File "/home/arthur/.mlflow/envs/mlflow-ee2151125638920885a7c5b8ea4d8ebbb2e906cb/lib/python3.10/site-packages/click/core.py", line 1078, in main
    rv = self.invoke(ctx)
  File "/home/arthur/.mlflow/envs/mlflow-ee2151125638920885a7c5b8ea4d8ebbb2e906cb/lib/python3.10/site-packages/click/core.py", line 1434, in invoke
    return ctx.invoke(self.callback, **ctx.params)
  File "/home/arthur/.mlflow/envs/mlflow-ee2151125638920885a7c5b8ea4d8ebbb2e906cb/lib/python3.10/site-packages/click/core.py", line 783, in invoke
    return __callback(*args, **kwargs)
  File "/home/arthur/Documents/ifc/tc/code/sipd-mlops/cmd/main.py", line 33, in workflow
    _run("train")
  File "/home/arthur/Documents/ifc/tc/code/sipd-mlops/cmd/main.py", line 16, in _run
    submitted_run = mlflow.run(".", entrypoint)
  File "/home/arthur/.mlflow/envs/mlflow-ee2151125638920885a7c5b8ea4d8ebbb2e906cb/lib/python3.10/site-packages/mlflow/projects/__init__.py", line 337, in run
    submitted_run_obj = _run(
  File "/home/arthur/.mlflow/envs/mlflow-ee2151125638920885a7c5b8ea4d8ebbb2e906cb/lib/python3.10/site-packages/mlflow/projects/__init__.py", line 106, in _run
    submitted_run = backend.run(
  File "/home/arthur/.mlflow/envs/mlflow-ee2151125638920885a7c5b8ea4d8ebbb2e906cb/lib/python3.10/site-packages/mlflow/projects/backend/local.py", line 80, in run
    work_dir = fetch_and_validate_project(project_uri, version, entry_point, params)
  File "/home/arthur/.mlflow/envs/mlflow-ee2151125638920885a7c5b8ea4d8ebbb2e906cb/lib/python3.10/site-packages/mlflow/projects/utils.py", line 140, in fetch_and_validate_project
    project.get_entry_point(entry_point)._validate_parameters(parameters)
  File "/home/arthur/.mlflow/envs/mlflow-ee2151125638920885a7c5b8ea4d8ebbb2e906cb/lib/python3.10/site-packages/mlflow/projects/_project_spec.py", line 174, in get_entry_point
    raise ExecutionException(
mlflow.exceptions.ExecutionException: Could not find train among entry points ['prepare_train_dataset', 'prepare_test_dataset', 'prepare_experiments_dataset', 'main', 'validate'] or interpret train as a runnable script. Supported script file extensions: ['.py', '.sh']

__main__ - ERROR - 2023-10-14 15:56:56,198 - Failed to run workflow due to error:
Could not find train among entry points ['prepare_train_dataset', 'prepare_test_dataset', 'prepare_experiments_dataset', 'main', 'validate'] or interpret train as a runnable script. Supported script file extensions: ['.py', '.sh']
__main__ - ERROR - 2023-10-14 15:56:56,199 - Traceback (most recent call last):
  File "/home/arthur/Documents/ifc/tc/code/sipd-mlops/cmd/main.py", line 48, in <module>
    workflow()
  File "/home/arthur/.mlflow/envs/mlflow-ee2151125638920885a7c5b8ea4d8ebbb2e906cb/lib/python3.10/site-packages/click/core.py", line 1157, in __call__
    return self.main(*args, **kwargs)
  File "/home/arthur/.mlflow/envs/mlflow-ee2151125638920885a7c5b8ea4d8ebbb2e906cb/lib/python3.10/site-packages/click/core.py", line 1078, in main
    rv = self.invoke(ctx)
  File "/home/arthur/.mlflow/envs/mlflow-ee2151125638920885a7c5b8ea4d8ebbb2e906cb/lib/python3.10/site-packages/click/core.py", line 1434, in invoke
    return ctx.invoke(self.callback, **ctx.params)
  File "/home/arthur/.mlflow/envs/mlflow-ee2151125638920885a7c5b8ea4d8ebbb2e906cb/lib/python3.10/site-packages/click/core.py", line 783, in invoke
    return __callback(*args, **kwargs)
  File "/home/arthur/Documents/ifc/tc/code/sipd-mlops/cmd/main.py", line 33, in workflow
    _run("train")
  File "/home/arthur/Documents/ifc/tc/code/sipd-mlops/cmd/main.py", line 16, in _run
    submitted_run = mlflow.run(".", entrypoint)
  File "/home/arthur/.mlflow/envs/mlflow-ee2151125638920885a7c5b8ea4d8ebbb2e906cb/lib/python3.10/site-packages/mlflow/projects/__init__.py", line 337, in run
    submitted_run_obj = _run(
  File "/home/arthur/.mlflow/envs/mlflow-ee2151125638920885a7c5b8ea4d8ebbb2e906cb/lib/python3.10/site-packages/mlflow/projects/__init__.py", line 106, in _run
    submitted_run = backend.run(
  File "/home/arthur/.mlflow/envs/mlflow-ee2151125638920885a7c5b8ea4d8ebbb2e906cb/lib/python3.10/site-packages/mlflow/projects/backend/local.py", line 80, in run
    work_dir = fetch_and_validate_project(project_uri, version, entry_point, params)
  File "/home/arthur/.mlflow/envs/mlflow-ee2151125638920885a7c5b8ea4d8ebbb2e906cb/lib/python3.10/site-packages/mlflow/projects/utils.py", line 140, in fetch_and_validate_project
    project.get_entry_point(entry_point)._validate_parameters(parameters)
  File "/home/arthur/.mlflow/envs/mlflow-ee2151125638920885a7c5b8ea4d8ebbb2e906cb/lib/python3.10/site-packages/mlflow/projects/_project_spec.py", line 174, in get_entry_point
    raise ExecutionException(
mlflow.exceptions.ExecutionException: Could not find train among entry points ['prepare_train_dataset', 'prepare_test_dataset', 'prepare_experiments_dataset', 'main', 'validate'] or interpret train as a runnable script. Supported script file extensions: ['.py', '.sh']

__main__ - ERROR - 2023-10-14 15:57:40,430 - Failed to run workflow due to error:
Could not find test among entry points ['prepare_train_dataset', 'prepare_test_dataset', 'prepare_experiments_dataset', 'train', 'validate', 'main'] or interpret test as a runnable script. Supported script file extensions: ['.py', '.sh']
__main__ - ERROR - 2023-10-14 15:57:40,430 - Traceback (most recent call last):
  File "/home/arthur/Documents/ifc/tc/code/sipd-mlops/cmd/main.py", line 48, in <module>
    workflow()
  File "/home/arthur/.mlflow/envs/mlflow-ee2151125638920885a7c5b8ea4d8ebbb2e906cb/lib/python3.10/site-packages/click/core.py", line 1157, in __call__
    return self.main(*args, **kwargs)
  File "/home/arthur/.mlflow/envs/mlflow-ee2151125638920885a7c5b8ea4d8ebbb2e906cb/lib/python3.10/site-packages/click/core.py", line 1078, in main
    rv = self.invoke(ctx)
  File "/home/arthur/.mlflow/envs/mlflow-ee2151125638920885a7c5b8ea4d8ebbb2e906cb/lib/python3.10/site-packages/click/core.py", line 1434, in invoke
    return ctx.invoke(self.callback, **ctx.params)
  File "/home/arthur/.mlflow/envs/mlflow-ee2151125638920885a7c5b8ea4d8ebbb2e906cb/lib/python3.10/site-packages/click/core.py", line 783, in invoke
    return __callback(*args, **kwargs)
  File "/home/arthur/Documents/ifc/tc/code/sipd-mlops/cmd/main.py", line 34, in workflow
    _run("test")
  File "/home/arthur/Documents/ifc/tc/code/sipd-mlops/cmd/main.py", line 16, in _run
    submitted_run = mlflow.run(".", entrypoint)
  File "/home/arthur/.mlflow/envs/mlflow-ee2151125638920885a7c5b8ea4d8ebbb2e906cb/lib/python3.10/site-packages/mlflow/projects/__init__.py", line 337, in run
    submitted_run_obj = _run(
  File "/home/arthur/.mlflow/envs/mlflow-ee2151125638920885a7c5b8ea4d8ebbb2e906cb/lib/python3.10/site-packages/mlflow/projects/__init__.py", line 106, in _run
    submitted_run = backend.run(
  File "/home/arthur/.mlflow/envs/mlflow-ee2151125638920885a7c5b8ea4d8ebbb2e906cb/lib/python3.10/site-packages/mlflow/projects/backend/local.py", line 80, in run
    work_dir = fetch_and_validate_project(project_uri, version, entry_point, params)
  File "/home/arthur/.mlflow/envs/mlflow-ee2151125638920885a7c5b8ea4d8ebbb2e906cb/lib/python3.10/site-packages/mlflow/projects/utils.py", line 140, in fetch_and_validate_project
    project.get_entry_point(entry_point)._validate_parameters(parameters)
  File "/home/arthur/.mlflow/envs/mlflow-ee2151125638920885a7c5b8ea4d8ebbb2e906cb/lib/python3.10/site-packages/mlflow/projects/_project_spec.py", line 174, in get_entry_point
    raise ExecutionException(
mlflow.exceptions.ExecutionException: Could not find test among entry points ['prepare_train_dataset', 'prepare_test_dataset', 'prepare_experiments_dataset', 'train', 'validate', 'main'] or interpret test as a runnable script. Supported script file extensions: ['.py', '.sh']

